terminate called after throwing an instance of 'std::runtime_error'
  what():  invalid args: fusion does not exist
